<?xml version="1.0"?>
<robot name="mars_rover_walle_inspired">

  <!-- Materials for URDF rendering in RViz -->
  <material name="WallEYellowOchre">
    <color rgba="0.95 0.78 0.3 1"/>
  </material>
  <material name="WheelBlack">
    <color rgba="0.05 0.05 0.05 1"/>
  </material>
  <material name="HubMetalDark">
    <color rgba="0.4 0.4 0.45 1"/>
  </material>
  <material name="EyeLensBlack">
    <color rgba="0.01 0.01 0.01 1"/>
  </material>
  <material name="EyeCasingGrey">
    <color rgba="0.6 0.6 0.6 1"/>
  </material>
  <material name="AccentRed">
    <color rgba="0.8 0.1 0.1 1"/>
  </material>

  <!-- Base Link with Corrected Inertia -->
  <link name="base_link">
    <visual name="chassis_visual">
      <geometry><box size="0.6 0.4 0.15"/></geometry>
      <material name="WallEYellowOchre"/>
    </visual>
    
    <!-- Eyes and Accent Light -->
    <visual name="right_eye_casing">
      <origin xyz="0.2 0.08 0.11" rpy="0 1.5708 0"/>
      <geometry><cylinder radius="0.06" length="0.12"/></geometry>
      <material name="EyeCasingGrey"/>
    </visual>
    <visual name="right_eye_lens">
      <origin xyz="0.26 0.08 0.11" rpy="0 0 0"/>
      <geometry><sphere radius="0.045"/></geometry>
      <material name="EyeLensBlack"/>
    </visual>
    <visual name="left_eye_casing">
      <origin xyz="0.2 -0.08 0.11" rpy="0 1.5708 0"/>
      <geometry><cylinder radius="0.06" length="0.12"/></geometry>
      <material name="EyeCasingGrey"/>
    </visual>
    <visual name="left_eye_lens">
      <origin xyz="0.26 -0.08 0.11" rpy="0 0 0"/>
      <geometry><sphere radius="0.045"/></geometry>
      <material name="EyeLensBlack"/>
    </visual>
    <visual name="accent_light">
      <origin xyz="-0.25 0 0.05" rpy="0 0 0"/>
      <geometry><box size="0.03 0.05 0.03"/></geometry>
      <material name="AccentRed"/>
    </visual>

    <collision>
      <geometry><box size="0.6 0.4 0.15"/></geometry>
      <surface>
        <friction>
          <ode>
            <mu>2.5</mu>
            <mu2>2.5</mu2>
            <slip1>0.0</slip1>
            <slip2>0.0</slip2>
            <fdir1>0 0 0</fdir1>
          </ode>
        </friction>
      </surface>
    </collision>
    <inertial>
      <mass value="5.0"/>
      <inertia 
        ixx="0.0833" ixy="0.0" ixz="0.0"
        iyy="0.1258" iyz="0.0"
        izz="0.0458"/>
    </inertial>
  </link>

  <!-- Wheels with Enhanced Friction -->
  <link name="left_drive_wheel">
    <visual name="tire_visual">
      <origin rpy="1.5708 0 0"/>
      <geometry><cylinder length="0.05" radius="0.08"/></geometry>
      <material name="WheelBlack"/>
    </visual>
    <visual name="hub_visual">
      <origin rpy="1.5708 0 0"/>
      <geometry><cylinder length="0.06" radius="0.04"/></geometry>
      <material name="HubMetalDark"/>
    </visual>
    <collision>
      <origin rpy="1.5708 0 0"/>
      <geometry><cylinder length="0.05" radius="0.08"/></geometry>
      <surface>
        <friction>
          <ode>
            <mu>10.0</mu>
            <mu2>10.0</mu2>
            <slip1>0.0001</slip1>
            <slip2>0.0001</slip2>
          </ode>
        </friction>
      </surface>
    </collision>
    <inertial>
      <mass value="0.5"/>
      <inertia 
        ixx="0.0016" ixy="0.0" ixz="0.0"
        iyy="0.0016" iyz="0.0"
        izz="0.0032"/>
    </inertial>
  </link>
  
  <joint name="left_drive_wheel_joint" type="continuous">
    <parent link="base_link"/>
    <child link="left_drive_wheel"/>
    <origin xyz="0 0.18 -0.075"/>
    <axis xyz="0 1 0"/>
    <dynamics damping="10.0" friction="10.0"/>
  </joint>

  <!-- Right Drive Wheel (mirror of left) -->
  <link name="right_drive_wheel">
    <visual name="tire_visual">
      <origin rpy="1.5708 0 0"/>
      <geometry><cylinder length="0.05" radius="0.08"/></geometry>
      <material name="WheelBlack"/>
    </visual>
    <visual name="hub_visual">
      <origin rpy="1.5708 0 0"/>
      <geometry><cylinder length="0.06" radius="0.04"/></geometry>
      <material name="HubMetalDark"/>
    </visual>
    <collision>
      <origin rpy="1.5708 0 0"/>
      <geometry><cylinder length="0.05" radius="0.08"/></geometry>
      <surface>
        <friction>
          <ode>
            <mu>10.0</mu>
            <mu2>10.0</mu2>
            <slip1>0.0001</slip1>
            <slip2>0.0001</slip2>
          </ode>
        </friction>
      </surface>
    </collision>
    <inertial>
      <mass value="0.5"/>
      <inertia 
        ixx="0.0016" ixy="0.0" ixz="0.0"
        iyy="0.0016" iyz="0.0"
        izz="0.0032"/>
    </inertial>
  </link>
  
  <joint name="right_drive_wheel_joint" type="continuous">
    <parent link="base_link"/>
    <child link="right_drive_wheel"/>
    <origin xyz="0 -0.18 -0.075"/>
    <axis xyz="0 1 0"/>
    <dynamics damping="10.0" friction="10.0"/>
  </joint>

  <!-- Idler Wheels (all 4 with identical enhanced friction) -->
  <!-- Front Left Idler -->
  <link name="left_idler_front">
    <visual name="tire_visual">
      <origin rpy="1.5708 0 0"/>
      <geometry><cylinder length="0.04" radius="0.05"/></geometry>
      <material name="WheelBlack"/>
    </visual>
    <visual name="hub_visual">
      <origin rpy="1.5708 0 0"/>
      <geometry><cylinder length="0.05" radius="0.025"/></geometry>
      <material name="HubMetalDark"/>
    </visual>
    <collision>
      <origin rpy="1.5708 0 0"/>
      <geometry><cylinder length="0.04" radius="0.05"/></geometry>
      <surface>
        <friction>
          <ode>
            <mu>8.0</mu>
            <mu2>8.0</mu2>
            <slip1>0.0001</slip1>
            <slip2>0.0001</slip2>
          </ode>
        </friction>
      </surface>
    </collision>
    <inertial>
      <mass value="0.1"/>
      <inertia 
        ixx="0.0004" ixy="0.0" ixz="0.0"
        iyy="0.0004" iyz="0.0"
        izz="0.0008"/>
    </inertial>
  </link>
  <joint name="left_idler_front_joint" type="continuous">
    <parent link="base_link"/>
    <child link="left_idler_front"/>
    <origin xyz="0.25 0.18 -0.075"/>
    <axis xyz="0 1 0"/>
    <dynamics damping="8.0" friction="8.0"/>
  </joint>

  <!-- Rear Left Idler -->
  <link name="left_idler_rear">
    <visual name="tire_visual">
      <origin rpy="1.5708 0 0"/>
      <geometry><cylinder length="0.04" radius="0.05"/></geometry>
      <material name="WheelBlack"/>
    </visual>
    <visual name="hub_visual">
      <origin rpy="1.5708 0 0"/>
      <geometry><cylinder length="0.05" radius="0.025"/></geometry>
      <material name="HubMetalDark"/>
    </visual>
    <collision>
      <origin rpy="1.5708 0 0"/>
      <geometry><cylinder length="0.04" radius="0.05"/></geometry>
      <surface>
        <friction>
          <ode>
            <mu>8.0</mu>
            <mu2>8.0</mu2>
            <slip1>0.0001</slip1>
            <slip2>0.0001</slip2>
          </ode>
        </friction>
      </surface>
    </collision>
    <inertial>
      <mass value="0.1"/>
      <inertia 
        ixx="0.0004" ixy="0.0" ixz="0.0"
        iyy="0.0004" iyz="0.0"
        izz="0.0008"/>
    </inertial>
  </link>
  <joint name="left_idler_rear_joint" type="continuous">
    <parent link="base_link"/>
    <child link="left_idler_rear"/>
    <origin xyz="-0.25 0.18 -0.075"/>
    <axis xyz="0 1 0"/>
    <dynamics damping="8.0" friction="8.0"/>
  </joint>

  <!-- Front Right Idler -->
  <link name="right_idler_front">
    <visual name="tire_visual">
      <origin rpy="1.5708 0 0"/>
      <geometry><cylinder length="0.04" radius="0.05"/></geometry>
      <material name="WheelBlack"/>
    </visual>
    <visual name="hub_visual">
      <origin rpy="1.5708 0 0"/>
      <geometry><cylinder length="0.05" radius="0.025"/></geometry>
      <material name="HubMetalDark"/>
    </visual>
    <collision>
      <origin rpy="1.5708 0 0"/>
      <geometry><cylinder length="0.04" radius="0.05"/></geometry>
      <surface>
        <friction>
          <ode>
            <mu>8.0</mu>
            <mu2>8.0</mu2>
            <slip1>0.0001</slip1>
            <slip2>0.0001</slip2>
          </ode>
        </friction>
      </surface>
    </collision>
    <inertial>
      <mass value="0.1"/>
      <inertia 
        ixx="0.0004" ixy="0.0" ixz="0.0"
        iyy="0.0004" iyz="0.0"
        izz="0.0008"/>
    </inertial>
  </link>
  <joint name="right_idler_front_joint" type="continuous">
    <parent link="base_link"/>
    <child link="right_idler_front"/>
    <origin xyz="0.25 -0.18 -0.075"/>
    <axis xyz="0 1 0"/>
    <dynamics damping="8.0" friction="8.0"/>
  </joint>

  <!-- Rear Right Idler -->
  <link name="right_idler_rear">
    <visual name="tire_visual">
      <origin rpy="1.5708 0 0"/>
      <geometry><cylinder length="0.04" radius="0.05"/></geometry>
      <material name="WheelBlack"/>
    </visual>
    <visual name="hub_visual">
      <origin rpy="1.5708 0 0"/>
      <geometry><cylinder length="0.05" radius="0.025"/></geometry>
      <material name="HubMetalDark"/>
    </visual>
    <collision>
      <origin rpy="1.5708 0 0"/>
      <geometry><cylinder length="0.04" radius="0.05"/></geometry>
      <surface>
        <friction>
          <ode>
            <mu>8.0</mu>
            <mu2>8.0</mu2>
            <slip1>0.0001</slip1>
            <slip2>0.0001</slip2>
          </ode>
        </friction>
      </surface>
    </collision>
    <inertial>
      <mass value="0.1"/>
      <inertia 
        ixx="0.0004" ixy="0.0" ixz="0.0"
        iyy="0.0004" iyz="0.0"
        izz="0.0008"/>
    </inertial>
  </link>
  <joint name="right_idler_rear_joint" type="continuous">
    <parent link="base_link"/>
    <child link="right_idler_rear"/>
    <origin xyz="-0.25 -0.18 -0.075"/>
    <axis xyz="0 1 0"/>
    <dynamics damping="8.0" friction="8.0"/>
  </joint>

  <!-- Gazebo Color Configuration - This is the key part for colors in Gazebo -->
  <gazebo reference="base_link">
    <visual>
      <material>
        <script>
          <name>Gazebo/Orange</name>
          <uri>file://media/materials/scripts/gazebo.material</uri>
        </script>
      </material>
    </visual>
  </gazebo>

  <gazebo reference="right_eye_lens">
    <visual>
      <material>
        <script>
          <name>Gazebo/Black</name>
          <uri>file://media/materials/scripts/gazebo.material</uri>
        </script>
      </material>
    </visual>
  </gazebo>

  <gazebo reference="left_eye_lens">
    <visual>
      <material>
        <script>
          <name>Gazebo/Black</name>
          <uri>file://media/materials/scripts/gazebo.material</uri>
        </script>
      </material>
    </visual>
  </gazebo>

  <gazebo reference="right_eye_casing">
    <visual>
      <material>
        <script>
          <name>Gazebo/Grey</name>
          <uri>file://media/materials/scripts/gazebo.material</uri>
        </script>
      </material>
    </visual>
  </gazebo>

  <gazebo reference="left_eye_casing">
    <visual>
      <material>
        <script>
          <name>Gazebo/Grey</name>
          <uri>file://media/materials/scripts/gazebo.material</uri>
        </script>
      </material>
    </visual>
  </gazebo>

  <gazebo reference="accent_light">
    <visual>
      <material>
        <script>
          <name>Gazebo/Red</name>
          <uri>file://media/materials/scripts/gazebo.material</uri>
        </script>
      </material>
    </visual>
  </gazebo>

  <gazebo reference="left_drive_wheel">
    <visual>
      <material>
        <script>
          <name>Gazebo/Black</name>
          <uri>file://media/materials/scripts/gazebo.material</uri>
        </script>
      </material>
    </visual>
  </gazebo>

  <gazebo reference="right_drive_wheel">
    <visual>
      <material>
        <script>
          <name>Gazebo/Black</name>
          <uri>file://media/materials/scripts/gazebo.material</uri>
        </script>
      </material>
    </visual>
  </gazebo>

  <gazebo reference="left_idler_front">
    <visual>
      <material>
        <script>
          <name>Gazebo/Black</name>
          <uri>file://media/materials/scripts/gazebo.material</uri>
        </script>
      </material>
    </visual>
  </gazebo>

  <gazebo reference="left_idler_rear">
    <visual>
      <material>
        <script>
          <name>Gazebo/Black</name>
          <uri>file://media/materials/scripts/gazebo.material</uri>
        </script>
      </material>
    </visual>
  </gazebo>

  <gazebo reference="right_idler_front">
    <visual>
      <material>
        <script>
          <name>Gazebo/Black</name>
          <uri>file://media/materials/scripts/gazebo.material</uri>
        </script>
      </material>
    </visual>
  </gazebo>

  <gazebo reference="right_idler_rear">
    <visual>
      <material>
        <script>
          <name>Gazebo/Black</name>
          <uri>file://media/materials/scripts/gazebo.material</uri>
        </script>
      </material>
    </visual>
  </gazebo>

  <!-- Gazebo Plugin with Modified Parameters -->
  <gazebo>
    <plugin name="diff_drive" filename="libgazebo_ros_diff_drive.so">
      <update_rate>50.0</update_rate>
      <command_topic>cmd_vel</command_topic>
      <odometry_topic>odom</odometry_topic>
      <odometry_frame>odom</odometry_frame>
      <robot_base_frame>base_link</robot_base_frame>
      <wheel_separation>0.36</wheel_separation>
      <wheel_diameter>0.16</wheel_diameter>
      <max_wheel_torque>200</max_wheel_torque> <!-- Significantly increased -->
      <wheel_acceleration>0.5</wheel_acceleration> <!-- Further decreased -->
      <left_joint>left_drive_wheel_joint</left_joint>
      <right_joint>right_drive_wheel_joint</right_joint>
      <publish_odom>true</publish_odom>
      <publish_odom_tf>true</publish_odom_tf>
      <publish_wheel_tf>false</publish_wheel_tf>
      <odometry_source>world</odometry_source>
      <robot_namespace>/</robot_namespace>
    </plugin>
  </gazebo>

</robot>
